Traceback (most recent call last):
  File "/Users/laurac/opt/anaconda3/envs/cc_indicators/lib/python3.12/site-packages/jupyter_cache/executors/utils.py", line 58, in single_nb_execution
    executenb(
  File "/Users/laurac/opt/anaconda3/envs/cc_indicators/lib/python3.12/site-packages/nbclient/client.py", line 1314, in execute
    return NotebookClient(nb=nb, resources=resources, km=km, **kwargs).execute()
           ^^^^^^^^^^^^^^^^^^^^^^^^^^^^^^^^^^^^^^^^^^^^^^^^^^^^^^^^^^^^^^^^^^^^^
  File "/Users/laurac/opt/anaconda3/envs/cc_indicators/lib/python3.12/site-packages/jupyter_core/utils/__init__.py", line 165, in wrapped
    return loop.run_until_complete(inner)
           ^^^^^^^^^^^^^^^^^^^^^^^^^^^^^^
  File "/Users/laurac/opt/anaconda3/envs/cc_indicators/lib/python3.12/asyncio/base_events.py", line 664, in run_until_complete
    return future.result()
           ^^^^^^^^^^^^^^^
  File "/Users/laurac/opt/anaconda3/envs/cc_indicators/lib/python3.12/site-packages/nbclient/client.py", line 709, in async_execute
    await self.async_execute_cell(
  File "/Users/laurac/opt/anaconda3/envs/cc_indicators/lib/python3.12/site-packages/nbclient/client.py", line 1062, in async_execute_cell
    await self._check_raise_for_error(cell, cell_index, exec_reply)
  File "/Users/laurac/opt/anaconda3/envs/cc_indicators/lib/python3.12/site-packages/nbclient/client.py", line 918, in _check_raise_for_error
    raise CellExecutionError.from_cell_and_msg(cell, exec_reply_content)
nbclient.exceptions.CellExecutionError: An error occurred while executing the following cell:
------------------
storms_severe.isel(date_time = 0).time.dt.year
storm_severe_params.first_date.dt.year
#storm_severe_params.oni_cat.values
------------------


[0;31m---------------------------------------------------------------------------[0m
[0;31mAttributeError[0m                            Traceback (most recent call last)
Cell [0;32mIn[26], line 2[0m
[1;32m      1[0m storms_severe[38;5;241m.[39misel(date_time [38;5;241m=[39m [38;5;241m0[39m)[38;5;241m.[39mtime[38;5;241m.[39mdt[38;5;241m.[39myear
[0;32m----> 2[0m [43mstorm_severe_params[49m[38;5;241;43m.[39;49m[43mfirst_date[49m[38;5;241m.[39mdt[38;5;241m.[39myear
[1;32m      3[0m [38;5;66;03m#storm_severe_params.oni_cat.values[39;00m

File [0;32m~/opt/anaconda3/envs/cc_indicators/lib/python3.12/site-packages/xarray/core/common.py:302[0m, in [0;36mAttrAccessMixin.__getattr__[0;34m(self, name)[0m
[1;32m    300[0m         [38;5;28;01mwith[39;00m suppress([38;5;167;01mKeyError[39;00m):
[1;32m    301[0m             [38;5;28;01mreturn[39;00m source[name]
[0;32m--> 302[0m [38;5;28;01mraise[39;00m [38;5;167;01mAttributeError[39;00m(
[1;32m    303[0m     [38;5;124mf[39m[38;5;124m"[39m[38;5;132;01m{[39;00m[38;5;28mtype[39m([38;5;28mself[39m)[38;5;241m.[39m[38;5;18m__name__[39m[38;5;132;01m!r}[39;00m[38;5;124m object has no attribute [39m[38;5;132;01m{[39;00mname[38;5;132;01m!r}[39;00m[38;5;124m"[39m
[1;32m    304[0m )

[0;31mAttributeError[0m: 'Dataset' object has no attribute 'first_date'

