Traceback (most recent call last):
  File "/Users/laurac/opt/anaconda3/envs/cc_indicators/lib/python3.12/site-packages/jupyter_cache/executors/utils.py", line 58, in single_nb_execution
    executenb(
  File "/Users/laurac/opt/anaconda3/envs/cc_indicators/lib/python3.12/site-packages/nbclient/client.py", line 1314, in execute
    return NotebookClient(nb=nb, resources=resources, km=km, **kwargs).execute()
           ^^^^^^^^^^^^^^^^^^^^^^^^^^^^^^^^^^^^^^^^^^^^^^^^^^^^^^^^^^^^^^^^^^^^^
  File "/Users/laurac/opt/anaconda3/envs/cc_indicators/lib/python3.12/site-packages/jupyter_core/utils/__init__.py", line 165, in wrapped
    return loop.run_until_complete(inner)
           ^^^^^^^^^^^^^^^^^^^^^^^^^^^^^^
  File "/Users/laurac/opt/anaconda3/envs/cc_indicators/lib/python3.12/asyncio/base_events.py", line 664, in run_until_complete
    return future.result()
           ^^^^^^^^^^^^^^^
  File "/Users/laurac/opt/anaconda3/envs/cc_indicators/lib/python3.12/site-packages/nbclient/client.py", line 709, in async_execute
    await self.async_execute_cell(
  File "/Users/laurac/opt/anaconda3/envs/cc_indicators/lib/python3.12/site-packages/nbclient/client.py", line 1062, in async_execute_cell
    await self._check_raise_for_error(cell, cell_index, exec_reply)
  File "/Users/laurac/opt/anaconda3/envs/cc_indicators/lib/python3.12/site-packages/nbclient/client.py", line 918, in _check_raise_for_error
    raise CellExecutionError.from_cell_and_msg(cell, exec_reply_content)
nbclient.exceptions.CellExecutionError: An error occurred while executing the following cell:
------------------
datam = data_mean.groupby(data_mean.index.year).mean()
datam.index = pd.to_datetime(datag.index, format = '%Y')
dict_plot = [{'data' : datam, 'var' : 'sst', 'ax' : 1, 'label':f'Annual Mean'},]
ax = plot_bar_probs(x = datam.index.year, y = datam.sst.values, trendline=True, figsize = (15, 6),
                y_label = 'Mean SST [ÂºC]')
ax.set_ylim([27, None])
------------------


[0;31m---------------------------------------------------------------------------[0m
[0;31mAttributeError[0m                            Traceback (most recent call last)
Cell [0;32mIn[11], line 6[0m
[1;32m      3[0m dict_plot [38;5;241m=[39m [{[38;5;124m'[39m[38;5;124mdata[39m[38;5;124m'[39m : datam, [38;5;124m'[39m[38;5;124mvar[39m[38;5;124m'[39m : [38;5;124m'[39m[38;5;124msst[39m[38;5;124m'[39m, [38;5;124m'[39m[38;5;124max[39m[38;5;124m'[39m : [38;5;241m1[39m, [38;5;124m'[39m[38;5;124mlabel[39m[38;5;124m'[39m:[38;5;124mf[39m[38;5;124m'[39m[38;5;124mAnnual Mean[39m[38;5;124m'[39m},]
[1;32m      4[0m ax [38;5;241m=[39m plot_bar_probs(x [38;5;241m=[39m datam[38;5;241m.[39mindex[38;5;241m.[39myear, y [38;5;241m=[39m datam[38;5;241m.[39msst[38;5;241m.[39mvalues, trendline[38;5;241m=[39m[38;5;28;01mTrue[39;00m, figsize [38;5;241m=[39m ([38;5;241m15[39m, [38;5;241m6[39m),
[1;32m      5[0m                 y_label [38;5;241m=[39m [38;5;124m'[39m[38;5;124mMean SST [ÂºC][39m[38;5;124m'[39m)
[0;32m----> 6[0m [43max[49m[38;5;241;43m.[39;49m[43mset_ylim[49m([[38;5;241m27[39m, [38;5;28;01mNone[39;00m])

[0;31mAttributeError[0m: 'tuple' object has no attribute 'set_ylim'

