Traceback (most recent call last):
  File "/Users/laurac/opt/anaconda3/envs/cc_indicators/lib/python3.12/site-packages/jupyter_cache/executors/utils.py", line 58, in single_nb_execution
    executenb(
  File "/Users/laurac/opt/anaconda3/envs/cc_indicators/lib/python3.12/site-packages/nbclient/client.py", line 1314, in execute
    return NotebookClient(nb=nb, resources=resources, km=km, **kwargs).execute()
           ^^^^^^^^^^^^^^^^^^^^^^^^^^^^^^^^^^^^^^^^^^^^^^^^^^^^^^^^^^^^^^^^^^^^^
  File "/Users/laurac/opt/anaconda3/envs/cc_indicators/lib/python3.12/site-packages/jupyter_core/utils/__init__.py", line 165, in wrapped
    return loop.run_until_complete(inner)
           ^^^^^^^^^^^^^^^^^^^^^^^^^^^^^^
  File "/Users/laurac/opt/anaconda3/envs/cc_indicators/lib/python3.12/asyncio/base_events.py", line 664, in run_until_complete
    return future.result()
           ^^^^^^^^^^^^^^^
  File "/Users/laurac/opt/anaconda3/envs/cc_indicators/lib/python3.12/site-packages/nbclient/client.py", line 709, in async_execute
    await self.async_execute_cell(
  File "/Users/laurac/opt/anaconda3/envs/cc_indicators/lib/python3.12/site-packages/nbclient/client.py", line 1062, in async_execute_cell
    await self._check_raise_for_error(cell, cell_index, exec_reply)
  File "/Users/laurac/opt/anaconda3/envs/cc_indicators/lib/python3.12/site-packages/nbclient/client.py", line 918, in _check_raise_for_error
    raise CellExecutionError.from_cell_and_msg(cell, exec_reply_content)
nbclient.exceptions.CellExecutionError: An error occurred while executing the following cell:
------------------
base_url = 'https://oceanwatch.pifsc.noaa.gov/erddap/griddap/esa-cci-chla-monthly-v6-0.csv'
dataset_id = 'chlor_a'
if update_data:
    date_ini = '1998-01-01T00:00:00Z'
    date_end = '2023-12-01T00:00:00Z'
    data = download_ERDDAP_data(base_url, dataset_id, date_ini, date_end, lon_range, lat_range)
    data_xr = data.set_index(['latitude', 'longitude', 'time']).to_xarray()
    data_xr['time'] = pd.to_datetime(data_xr.time)
    data_xr = data_xr.coarsen(longitude=2, latitude=2, boundary = 'pad').mean()
    data_xr.to_netcdf(op.join(path_data, f'griddap_{dataset_id}.nc'))
else:
    data_xr = xr.open_dataset(op.join(path_data, f'griddap_{dataset_id}.nc'))
------------------


[0;31m---------------------------------------------------------------------------[0m
[0;31mNameError[0m                                 Traceback (most recent call last)
Cell [0;32mIn[6], line 12[0m
[1;32m     10[0m     data_xr[38;5;241m.[39mto_netcdf(op[38;5;241m.[39mjoin(path_data, [38;5;124mf[39m[38;5;124m'[39m[38;5;124mgriddap_[39m[38;5;132;01m{[39;00mdataset_id[38;5;132;01m}[39;00m[38;5;124m.nc[39m[38;5;124m'[39m))
[1;32m     11[0m [38;5;28;01melse[39;00m:
[0;32m---> 12[0m     data_xr [38;5;241m=[39m [43mxr[49m[38;5;241m.[39mopen_dataset(op[38;5;241m.[39mjoin(path_data, [38;5;124mf[39m[38;5;124m'[39m[38;5;124mgriddap_[39m[38;5;132;01m{[39;00mdataset_id[38;5;132;01m}[39;00m[38;5;124m.nc[39m[38;5;124m'[39m))

[0;31mNameError[0m: name 'xr' is not defined

