Traceback (most recent call last):
  File "/Users/laurac/opt/anaconda3/envs/cc_indicators/lib/python3.12/site-packages/jupyter_cache/executors/utils.py", line 58, in single_nb_execution
    executenb(
  File "/Users/laurac/opt/anaconda3/envs/cc_indicators/lib/python3.12/site-packages/nbclient/client.py", line 1314, in execute
    return NotebookClient(nb=nb, resources=resources, km=km, **kwargs).execute()
           ^^^^^^^^^^^^^^^^^^^^^^^^^^^^^^^^^^^^^^^^^^^^^^^^^^^^^^^^^^^^^^^^^^^^^
  File "/Users/laurac/opt/anaconda3/envs/cc_indicators/lib/python3.12/site-packages/jupyter_core/utils/__init__.py", line 165, in wrapped
    return loop.run_until_complete(inner)
           ^^^^^^^^^^^^^^^^^^^^^^^^^^^^^^
  File "/Users/laurac/opt/anaconda3/envs/cc_indicators/lib/python3.12/asyncio/base_events.py", line 664, in run_until_complete
    return future.result()
           ^^^^^^^^^^^^^^^
  File "/Users/laurac/opt/anaconda3/envs/cc_indicators/lib/python3.12/site-packages/nbclient/client.py", line 709, in async_execute
    await self.async_execute_cell(
  File "/Users/laurac/opt/anaconda3/envs/cc_indicators/lib/python3.12/site-packages/nbclient/client.py", line 1062, in async_execute_cell
    await self._check_raise_for_error(cell, cell_index, exec_reply)
  File "/Users/laurac/opt/anaconda3/envs/cc_indicators/lib/python3.12/site-packages/nbclient/client.py", line 918, in _check_raise_for_error
    raise CellExecutionError.from_cell_and_msg(cell, exec_reply_content)
nbclient.exceptions.CellExecutionError: An error occurred while executing the following cell:
------------------
if update_data:
    df_country = GHCN.get_country_code(country)
    print(f'The GHCN code for {country} is {df_country["Code"].values[0]}')

    df_stations = GHCN.download_stations_info()
    df_country_stations = df_stations[df_stations['ID'].str.startswith(df_country.Code.values[0])]
    print(f'There are {df_country_stations.shape[0]} stations in {country}')
------------------


[0;31m---------------------------------------------------------------------------[0m
[0;31mNameError[0m                                 Traceback (most recent call last)
Cell [0;32mIn[3], line 1[0m
[0;32m----> 1[0m [38;5;28;01mif[39;00m [43mupdate_data[49m:
[1;32m      2[0m     df_country [38;5;241m=[39m GHCN[38;5;241m.[39mget_country_code(country)
[1;32m      3[0m     [38;5;28mprint[39m([38;5;124mf[39m[38;5;124m'[39m[38;5;124mThe GHCN code for [39m[38;5;132;01m{[39;00mcountry[38;5;132;01m}[39;00m[38;5;124m is [39m[38;5;132;01m{[39;00mdf_country[[38;5;124m"[39m[38;5;124mCode[39m[38;5;124m"[39m][38;5;241m.[39mvalues[[38;5;241m0[39m][38;5;132;01m}[39;00m[38;5;124m'[39m)

[0;31mNameError[0m: name 'update_data' is not defined

