Traceback (most recent call last):
  File "/Users/laurac/opt/anaconda3/envs/cc_indicators_v2/lib/python3.12/site-packages/jupyter_cache/executors/utils.py", line 58, in single_nb_execution
    executenb(
  File "/Users/laurac/opt/anaconda3/envs/cc_indicators_v2/lib/python3.12/site-packages/nbclient/client.py", line 1319, in execute
    return NotebookClient(nb=nb, resources=resources, km=km, **kwargs).execute()
           ^^^^^^^^^^^^^^^^^^^^^^^^^^^^^^^^^^^^^^^^^^^^^^^^^^^^^^^^^^^^^^^^^^^^^
  File "/Users/laurac/opt/anaconda3/envs/cc_indicators_v2/lib/python3.12/site-packages/jupyter_core/utils/__init__.py", line 165, in wrapped
    return loop.run_until_complete(inner)
           ^^^^^^^^^^^^^^^^^^^^^^^^^^^^^^
  File "/Users/laurac/opt/anaconda3/envs/cc_indicators_v2/lib/python3.12/asyncio/base_events.py", line 664, in run_until_complete
    return future.result()
           ^^^^^^^^^^^^^^^
  File "/Users/laurac/opt/anaconda3/envs/cc_indicators_v2/lib/python3.12/site-packages/nbclient/client.py", line 709, in async_execute
    await self.async_execute_cell(
  File "/Users/laurac/opt/anaconda3/envs/cc_indicators_v2/lib/python3.12/site-packages/nbclient/client.py", line 1062, in async_execute_cell
    await self._check_raise_for_error(cell, cell_index, exec_reply)
  File "/Users/laurac/opt/anaconda3/envs/cc_indicators_v2/lib/python3.12/site-packages/nbclient/client.py", line 918, in _check_raise_for_error
    raise CellExecutionError.from_cell_and_msg(cell, exec_reply_content)
nbclient.exceptions.CellExecutionError: An error occurred while executing the following cell:
------------------
import warnings
warnings.filterwarnings("ignore")
import sys
import os.path as op
import xarray as xr
import pandas as pd
import requests
from io import BytesIO
import numpy as np
import matplotlib.pyplot as plt

sys.path.append("../../../functions")
from tcs import Extract_Circle
from data_downloaders import download_ibtracs

sys.path.append("../../../../indicators_setup")
from ind_setup.plotting_tcs import Plot_TCs_HistoricalTracks_Category
from ind_setup.plotting import plot_bar_probs, plot_tc_categories_trend
from ind_setup.tables import plot_df_table

from ind_setup.plotting import plot_bar_probs_ONI, add_oni_cat
from data_downloaders import  download_oni_index

------------------


[0;31m---------------------------------------------------------------------------[0m
[0;31mModuleNotFoundError[0m                       Traceback (most recent call last)
Cell [0;32mIn[1], line 13[0m
[1;32m     10[0m [38;5;28;01mimport[39;00m[38;5;250m [39m[38;5;21;01mmatplotlib[39;00m[38;5;21;01m.[39;00m[38;5;21;01mpyplot[39;00m[38;5;250m [39m[38;5;28;01mas[39;00m[38;5;250m [39m[38;5;21;01mplt[39;00m
[1;32m     12[0m sys[38;5;241m.[39mpath[38;5;241m.[39mappend([38;5;124m"[39m[38;5;124m../../../functions[39m[38;5;124m"[39m)
[0;32m---> 13[0m [38;5;28;01mfrom[39;00m[38;5;250m [39m[38;5;21;01mtcs[39;00m[38;5;250m [39m[38;5;28;01mimport[39;00m Extract_Circle
[1;32m     14[0m [38;5;28;01mfrom[39;00m[38;5;250m [39m[38;5;21;01mdata_downloaders[39;00m[38;5;250m [39m[38;5;28;01mimport[39;00m download_ibtracs
[1;32m     16[0m sys[38;5;241m.[39mpath[38;5;241m.[39mappend([38;5;124m"[39m[38;5;124m../../../../indicators_setup[39m[38;5;124m"[39m)

[0;31mModuleNotFoundError[0m: No module named 'tcs'

